File: Carbon fiber Load Testing.csv
Time,Extension,Load,Compressive stress,Displacement (Strain 1),,
(sec),(mm),(N),(MPa),(mm),,
0,-0.75754,-3.13492,0.02004,0.00003,,
0.0268,-0.75759,-5.34439,0.03416,0.00003,,
0.0498,-0.75811,-6.54487,0.04183,0.00003,,
0.0798,-0.76011,-6.00773,0.0384,0.00003,,
0.1058,-0.76295,-6.10193,0.039,0.00003,,
0.1338,-0.76652,-6.04941,0.03867,0.00003,,
0.1598,-0.76975,-5.80279,0.03709,0.00003,,
0.1858,-0.77282,-6.39097,0.04085,0.00003,,
0.2138,-0.7759,-6.29714,0.04025,0.00003,,
0.2408,-0.77875,-5.91138,0.03778,0.00003,,
0.2628,-0.78105,-6.44317,0.04118,0.00003,,
0.2858,-0.78351,-6.5722,0.04201,0.00003,,
0.3148,-0.78655,-6.25984,0.04001,0.00003,,
0.3388,-0.78897,-6.573,0.04201,0.00003,,
0.3628,-0.79136,-6.54017,0.0418,0.00003,,
0.3838,-0.79349,-6.91093,0.04417,0.00003,,
0.4068,-0.79588,-6.29388,0.04023,0.00003,,
0.4418,-0.79944,-5.96433,0.03812,0.00003,,
0.4708,-0.80229,-5.60544,0.03583,0.00003,,
0.5,-0.80515,-5.85895,0.03745,0.00003,,
0.5238,-0.80761,-6.03497,0.03857,0.00003,,
0.5598,-0.81126,-5.43576,0.03474,0.00003,,
0.5838,-0.81361,-5.41583,0.03462,0.00003,,
0.6088,-0.81602,-5.92209,0.03785,0.00003,,
0.6428,-0.81946,-5.54956,0.03547,0.00003,,
0.6738,-0.82262,-5.18328,0.03313,0.00003,,
0.7008,-0.82528,-6.26463,0.04004,0.00003,,
0.7308,-0.82822,-5.71855,0.03655,0.00003,,
0.7538,-0.83054,-6.17546,0.03947,0.00003,,
0.7848,-0.8337,-6.38925,0.04084,0.00003,,
0.8128,-0.8365,-5.5037,0.03518,0.00003,,
0.8438,-0.83953,-5.60447,0.03582,0.00003,,
0.8738,-0.84256,-5.42304,0.03466,0.00003,,
0.9038,-0.84565,-5.61201,0.03587,0.00003,,
0.9348,-0.84874,-5.48749,0.03507,0.00003,,
0.9538,-0.85059,-5.80582,0.03711,0.00003,,
0.9908,-0.8543,-5.79334,0.03703,0.00003,,
1.0218,-0.8575,-5.66766,0.03623,0.00003,,
1.0458,-0.85989,-6.13364,0.0392,0.00003,,
1.0778,-0.86299,-6.01453,0.03844,0.00003,,
1.1068,-0.86588,-6.07418,0.03882,0.00003,,
1.1268,-0.86795,-6.21104,0.0397,0.00003,,
1.1508,-0.87038,-6.34962,0.04059,0.00003,,
1.1788,-0.87315,-5.93881,0.03796,0.00003,,
1.2,-0.87517,-6.42254,0.04105,0.00003,,
1.2288,-0.87804,-6.09714,0.03897,0.00003,,
1.2578,-0.88099,-6.01294,0.03843,0.00003,,
1.2888,-0.88407,-6.39022,0.04084,0.00003,,
1.3108,-0.88621,-5.73564,0.03666,0.00003,,
1.3388,-0.88897,-6.33574,0.0405,0.00003,,
1.3648,-0.89164,-6.71521,0.04292,0.00003,,
1.3858,-0.89377,-6.69854,0.04282,0.00003,,
1.4058,-0.89576,-7.32602,0.04683,0.00003,,
1.4308,-0.89823,-6.81956,0.04359,0.00003,,
1.4628,-0.90141,-6.48522,0.04145,0.00003,,
1.4968,-0.90489,-5.80223,0.03709,0.00003,,
1.5208,-0.90732,-5.74393,0.03671,0.00003,,
1.5468,-0.9099,-7.11456,0.04547,0.00003,,
1.5808,-0.91328,-6.45081,0.04123,0.00003,,
1.6048,-0.91573,-6.80839,0.04352,0.00003,,
1.6268,-0.91796,-7.27726,0.04651,0.00003,,
1.6548,-0.92074,-7.55689,0.0483,0.00003,,
1.6768,-0.92288,-8.01268,0.05122,0.00003,,
1.7008,-0.92526,-7.84835,0.05016,0.00003,,
1.7258,-0.92782,-7.87401,0.05033,0.00003,,
1.7538,-0.93064,-7.84155,0.05012,0.00003,,
1.7778,-0.933,-8.19173,0.05236,0.00003,,
1.8028,-0.93544,-8.75718,0.05597,0.00003,,
1.8368,-0.93888,-8.73404,0.05583,0.00003,,
1.8648,-0.94171,-8.80673,0.05629,0.00003,,
1.8938,-0.94457,-9.65232,0.0617,0.00003,,
1.9248,-0.94761,-9.93628,0.06351,0.00003,,
1.9438,-0.94952,-10.69498,0.06836,0.00003,,
1.9718,-0.95238,-11.57373,0.07398,0.00003,,
1.9918,-0.95438,-12.46561,0.07968,0.00003,,
2.0138,-0.95657,-13.0279,0.08327,0.00003,,
2.0388,-0.95905,-13.55913,0.08667,0.00003,,
2.0698,-0.9622,-14.05999,0.08987,0.00003,,
2.0948,-0.96473,-14.52616,0.09285,0.00003,,
2.1148,-0.96672,-16.13051,0.1031,0.00003,,
2.1438,-0.96959,-17.10961,0.10936,0.00003,,
2.1818,-0.9734,-17.48842,0.11178,0.00003,,
2.2008,-0.97534,-18.66221,0.11928,0.00003,,
2.2278,-0.97803,-20.61496,0.13177,0.00003,,
2.2548,-0.9807,-22.41977,0.1433,0.00003,,
2.2828,-0.98348,-23.80158,0.15213,0.00003,,
2.3068,-0.98593,-25.50781,0.16304,0.00003,,
2.3338,-0.98867,-27.28598,0.17441,0.00003,,
2.3578,-0.99103,-28.45214,0.18186,0.00003,,
2.3848,-0.99367,-29.53764,0.1888,0.00003,,
2.4108,-0.99625,-31.13379,0.199,0.00003,,
2.4448,-0.99972,-31.99247,0.20449,0.00003,,
2.4828,-1.00347,-33.54121,0.21439,0.00003,,
2.5038,-1.00552,-35.13019,0.22454,0.00003,,
2.5288,-1.00801,-36.38403,0.23256,0.00003,,
2.5558,-1.01076,-37.55689,0.24005,0.00003,,
2.5868,-1.01386,-38.22823,0.24435,0.00003,,
2.6068,-1.01583,-39.04924,0.24959,0.00003,,
2.6358,-1.0187,-39.95774,0.2554,0.00003,,
2.6628,-1.02145,-40.90853,0.26148,0.00003,,
2.6848,-1.02371,-42.05764,0.26882,0.00003,,
2.7078,-1.02598,-42.61686,0.2724,0.00003,,
2.7378,-1.02893,-42.7606,0.27332,0.00003,,
2.7698,-1.03216,-43.24145,0.27639,0.00003,,
2.8028,-1.03556,-43.43097,0.2776,0.00003,,
2.8258,-1.03783,-44.00737,0.28128,0.00003,,
2.8598,-1.04117,-44.65883,0.28545,0.00003,,
2.8828,-1.04347,-45.17417,0.28874,0.00003,,
2.9048,-1.04573,-45.4844,0.29073,0.00003,,
2.9308,-1.04837,-45.24095,0.28917,0.00003,,
2.9548,-1.05074,-45.32174,0.28969,0.00003,,
2.9788,-1.05308,-46.16701,0.29509,0.00003,,
3.0058,-1.05576,-46.24785,0.29561,0.00003,,
3.0318,-1.05843,-45.98484,0.29392,0.00003,,
3.0648,-1.06174,-46.2546,0.29565,0.00003,,
3.0958,-1.06475,-46.62909,0.29804,0.00003,,
3.1308,-1.06822,-46.8703,0.29958,0.00003,,
3.1508,-1.07027,-47.59603,0.30422,0.00003,,
3.1748,-1.0727,-48.17913,0.30795,0.00003,,
3.2048,-1.07566,-47.57526,0.30409,0.00003,,
3.2368,-1.0788,-47.22378,0.30184,0.00003,,
3.2588,-1.08104,-47.57019,0.30406,0.00003,,
3.2868,-1.0839,-48.06966,0.30725,0.00003,,
3.3178,-1.08699,-47.27375,0.30216,0.00003,,
3.3458,-1.08973,-46.82853,0.29932,0.00003,,
3.3698,-1.09215,-47.96162,0.30656,0.00003,,
3.3938,-1.09463,-47.80372,0.30555,0.00003,,
3.4168,-1.09696,-47.71757,0.305,0.00003,,
3.4498,-1.1002,-47.34523,0.30262,0.00003,,
3.4768,-1.10285,-47.3348,0.30255,0.00003,,
3.4978,-1.10501,-47.98765,0.30673,0.00003,,
3.5198,-1.10728,-48.31641,0.30883,0.00003,,
3.5438,-1.10968,-48.36032,0.30911,0.00003,,
3.5718,-1.1124,-47.89601,0.30614,0.00003,,
3.6,-1.11517,-47.70267,0.3049,0.00003,,
3.6248,-1.11774,-47.54537,0.3039,0.00003,,
3.6448,-1.11978,-48.1193,0.30757,0.00003,,
3.6768,-1.12295,-47.88958,0.3061,0.00003,,
3.7038,-1.12557,-47.80912,0.30558,0.00003,,
3.7258,-1.12776,-48.446,0.30966,0.00003,,
3.7538,-1.13061,-48.84182,0.31219,0.00003,,
3.7778,-1.133,-48.68554,0.31119,0.00003,,
3.8118,-1.13633,-47.48227,0.3035,0.00003,,
3.8428,-1.13941,-47.24166,0.30196,0.00003,,
3.8858,-1.14379,-47.02206,0.30055,0.00003,,
3.9028,-1.14549,-47.58011,0.30412,0.00003,,
3.9248,-1.14765,-48.16116,0.30783,0.00003,,
3.9488,-1.15003,-48.32926,0.30891,0.00003,,
3.9808,-1.15329,-47.93005,0.30636,0.00003,,
4.0128,-1.15653,-47.17652,0.30154,0.00003,,
4.0448,-1.15971,-47.05102,0.30074,0.00003,,
4.0698,-1.16217,-47.71347,0.30497,0.00003,,
4.0948,-1.16469,-47.94523,0.30645,0.00003,,
4.1168,-1.16694,-48.06737,0.30724,0.00003,,
4.1428,-1.16956,-48.00418,0.30683,0.00003,,
4.1808,-1.17329,-47.32301,0.30248,0.00003,,
4.2018,-1.17539,-47.75347,0.30523,0.00003,,
4.2188,-1.17714,-47.79408,0.30549,0.00003,,
4.2388,-1.17917,-48.45369,0.3097,0.00003,,
4.2668,-1.18196,-48.11566,0.30754,0.00003,,
4.2988,-1.18508,-47.19659,0.30167,0.00003,,
4.3218,-1.18738,-47.2649,0.30211,0.00003,,
4.3508,-1.19033,-47.56725,0.30404,0.00003,,
4.3768,-1.1929,-47.86728,0.30596,0.00003,,
4.4,-1.19517,-47.80693,0.30557,0.00003,,
4.4298,-1.19813,-47.4134,0.30306,0.00003,,
4.4598,-1.20118,-47.40753,0.30302,0.00003,,
4.4878,-1.204,-46.92627,0.29994,0.00003,,
4.5158,-1.20678,-47.40087,0.30298,0.00003,,
4.5368,-1.20885,-47.55636,0.30397,0.00003,,
4.5638,-1.21159,-47.23943,0.30194,0.00003,,
4.5998,-1.21525,-47.24534,0.30198,0.00003,,
4.6188,-1.21715,-47.6392,0.3045,0.00003,,
4.6468,-1.21993,-47.4053,0.303,0.00003,,
4.6718,-1.22243,-47.48586,0.30352,0.00003,,
4.6938,-1.22467,-47.83315,0.30574,0.00003,,
4.7188,-1.22719,-48.09042,0.30738,0.00003,,
4.7428,-1.22956,-47.86323,0.30593,0.00003,,
4.7738,-1.23261,-47.7517,0.30522,0.00003,,
4.7918,-1.23441,-48.39711,0.30934,0.00003,,
4.8228,-1.23758,-48.46496,0.30978,0.00003,,
4.8598,-1.24127,-47.24301,0.30197,0.00003,,
4.8838,-1.24361,-47.89294,0.30612,0.00003,,
4.9158,-1.2468,-47.84558,0.30582,0.00003,,
4.9458,-1.24987,-47.55482,0.30396,0.00003,,
4.9738,-1.25263,-48.08912,0.30737,0.00003,,
5,-1.25516,-48.31729,0.30883,0.00003,,
5.0268,-1.25782,-48.29266,0.30868,0.00003,,
5.0498,-1.26017,-47.98523,0.30671,0.00003,,
5.0788,-1.26308,-48.25988,0.30847,0.00003,,
5.1098,-1.26615,-48.11632,0.30755,0.00003,,
5.1408,-1.26923,-47.84851,0.30584,0.00003,,
5.1708,-1.27231,-47.61359,0.30433,0.00003,,
5.1968,-1.27493,-48.53159,0.3102,0.00003,,
5.2168,-1.2769,-49.0373,0.31343,0.00003,,
5.2458,-1.27975,-48.60335,0.31066,0.00003,,
5.2678,-1.28197,-48.54538,0.31029,0.00003,,
5.2908,-1.28435,-49.25556,0.31483,0.00003,,
5.3128,-1.28658,-48.87911,0.31242,0.00003,,
5.3428,-1.28952,-48.58649,0.31055,0.00003,,
5.3648,-1.29166,-48.52614,0.31017,0.00003,,
5.3888,-1.29409,-48.84945,0.31223,0.00003,,
5.4118,-1.29646,-48.95995,0.31294,0.00003,,
5.4428,-1.29958,-48.49946,0.31,0.00003,,
5.4768,-1.30291,-48.46407,0.30977,0.00003,,
5.5138,-1.30662,-47.77061,0.30534,0.00003,,
5.5508,-1.31039,-47.73294,0.3051,0.00003,,
5.5878,-1.31401,-48.17932,0.30795,0.00003,,
5.6158,-1.31672,-48.30612,0.30876,0.00003,,
5.6418,-1.31936,-48.63371,0.31086,0.00003,,
5.6718,-1.32243,-48.15701,0.30781,0.00003,,
5.6958,-1.32481,-48.31431,0.30881,0.00003,,
5.7198,-1.32715,-48.61271,0.31072,0.00003,,
5.7458,-1.32975,-48.58868,0.31057,0.00003,,
5.7778,-1.33303,-48.07273,0.30727,0.00003,,
5.8048,-1.33572,-48.2941,0.30868,0.00003,,
5.8458,-1.33974,-47.4419,0.30324,0.00003,,
5.8708,-1.34227,-47.95939,0.30655,0.00003,,
5.9008,-1.34537,-48.07203,0.30727,0.00003,,
5.9228,-1.34757,-48.62398,0.31079,0.00003,,
5.9498,-1.35023,-48.45206,0.30969,0.00003,,
5.9788,-1.35307,-47.98626,0.30672,0.00003,,
6.0028,-1.35555,-47.96959,0.30661,0.00003,,
6.0408,-1.35942,-47.9307,0.30636,0.00003,,
6.0638,-1.36167,-47.8772,0.30602,0.00003,,
6.0948,-1.36468,-47.89224,0.30612,0.00003,,
6.1238,-1.36764,-47.70793,0.30494,0.00003,,
6.1518,-1.37047,-48.57942,0.31051,0.00003,,
6.1788,-1.37312,-48.68316,0.31117,0.00003,,
6.1998,-1.37515,-49.17858,0.31434,0.00003,,
6.2248,-1.37761,-49.24377,0.31475,0.00003,,
6.2508,-1.38026,-49.31716,0.31522,0.00003,,
6.2748,-1.38267,-49.36275,0.31552,0.00003,,
6.3028,-1.38544,-49.55479,0.31674,0.00003,,
6.3258,-1.38768,-49.43116,0.31595,0.00003,,
6.3478,-1.3899,-50.54814,0.32309,0.00003,,
6.3788,-1.3931,-50.02501,0.31975,0.00003,,
6.4068,-1.39591,-49.61775,0.31714,0.00003,,
6.4298,-1.39818,-50.33948,0.32176,0.00003,,
6.4638,-1.40156,-50.41156,0.32222,0.00003,,
6.4888,-1.40413,-50.68327,0.32396,0.00003,,
6.5188,-1.40716,-51.09748,0.3266,0.00003,,
6.5428,-1.40954,-51.82778,0.33127,0.00003,,
6.5658,-1.4118,-52.04086,0.33263,0.00003,,
6.5868,-1.41391,-52.34233,0.33456,0.00003,,
6.6138,-1.41666,-52.27085,0.3341,0.00003,,
6.6408,-1.41938,-51.84938,0.33141,0.00003,,
6.6678,-1.42204,-52.41353,0.33501,0.00003,,
6.6928,-1.42449,-52.98709,0.33868,0.00003,,
6.7138,-1.42662,-53.56059,0.34235,0.00003,,
6.7398,-1.42927,-53.19021,0.33998,0.00003,,
6.7718,-1.43245,-53.0866,0.33932,0.00003,,
6.7998,-1.43518,-53.17568,0.33989,0.00003,,
6.8258,-1.4378,-52.82476,0.33764,0.00003,,
6.8558,-1.44085,-53.0906,0.33934,0.00003,,
6.8788,-1.44313,-54.16917,0.34624,0.00003,,
6.9,-1.4452,-55.09779,0.35217,0.00003,,
6.9238,-1.44755,-55.12978,0.35238,0.00003,,
6.9498,-1.45017,-55.27586,0.35331,0.00003,,
6.9788,-1.45312,-54.77127,0.35009,0.00003,,
7.0048,-1.45571,-54.71213,0.34971,0.00003,,
7.0348,-1.45866,-54.53145,0.34855,0.00003,,
7.0698,-1.46221,-54.39301,0.34767,0.00003,,
7.0998,-1.46524,-54.74561,0.34992,0.00003,,
7.1268,-1.46792,-55.11958,0.35231,0.00003,,
7.1618,-1.47141,-55.21677,0.35293,0.00003,,
7.1888,-1.47415,-55.2136,0.35291,0.00003,,
7.2138,-1.47668,-55.58436,0.35528,0.00003,,
7.2378,-1.47906,-55.89179,0.35725,0.00003,,
7.2558,-1.48084,-56.66679,0.3622,0.00003,,
7.2868,-1.48392,-55.70813,0.35607,0.00003,,
7.3128,-1.48658,-55.83917,0.35691,0.00003,,
7.3408,-1.4894,-55.44685,0.3544,0.00003,,
7.3648,-1.49177,-55.99377,0.3579,0.00003,,
7.3878,-1.49402,-56.63196,0.36198,0.00003,,
7.4168,-1.49691,-56.66632,0.3622,0.00003,,
7.4498,-1.50028,-56.85883,0.36343,0.00003,,
7.4718,-1.50245,-57.6335,0.36838,0.00003,,
7.5078,-1.50596,-57.68505,0.36871,0.00003,,
7.5388,-1.50905,-57.70796,0.36886,0.00003,,
7.5598,-1.51119,-58.66531,0.37497,0.00003,,
7.5898,-1.51418,-58.856,0.37619,0.00003,,
7.6098,-1.51616,-58.64515,0.37485,0.00003,,
7.6328,-1.51842,-59.01377,0.3772,0.00003,,
7.6558,-1.52075,-59.08371,0.37765,0.00003,,
7.6808,-1.52333,-58.90336,0.3765,0.00003,,
7.7048,-1.52571,-58.83267,0.37604,0.00003,,
7.7388,-1.52906,-58.87616,0.37632,0.00003,,
7.7688,-1.53209,-58.89796,0.37646,0.00003,,
7.8098,-1.53629,-57.89394,0.37004,0.00003,,
7.8358,-1.53884,-58.82075,0.37597,0.00003,,
7.8578,-1.541,-59.29326,0.37899,0.00003,,
7.8858,-1.54379,-59.02052,0.37725,0.00003,,
7.9148,-1.54678,-58.74508,0.37548,0.00003,,
7.9408,-1.54938,-59.06299,0.37752,0.00003,,
7.9698,-1.55223,-59.36702,0.37946,0.00003,,
8,-1.55518,-59.09214,0.3777,0.00003,,
8.0268,-1.55794,-59.24194,0.37866,0.00003,,
8.0548,-1.56078,-59.6147,0.38104,0.00003,,
8.0768,-1.56295,-60.42151,0.3862,0.00003,,
8.0988,-1.56507,-61.32675,0.39199,0.00003,,
8.1208,-1.56722,-61.31348,0.3919,0.00003,,
8.1558,-1.5708,-60.79893,0.38861,0.00003,,
8.1858,-1.57382,-60.60037,0.38734,0.00003,,
8.2048,-1.57569,-60.9098,0.38932,0.00003,,
8.2308,-1.57824,-61.32629,0.39198,0.00003,,
8.2568,-1.58087,-61.47129,0.39291,0.00003,,
8.2888,-1.58413,-60.741,0.38824,0.00003,,
8.3148,-1.58672,-60.83739,0.38886,0.00003,,
8.3428,-1.58944,-60.9024,0.38927,0.00003,,
8.3678,-1.59194,-61.22184,0.39132,0.00003,,
8.3958,-1.59483,-61.55483,0.39344,0.00003,,
8.4238,-1.59765,-61.71088,0.39444,0.00003,,
8.4468,-1.59991,-62.08275,0.39682,0.00003,,
8.4758,-1.60276,-63.32668,0.40477,0.00003,,
8.4978,-1.60501,-64.2803,0.41086,0.00003,,
8.5178,-1.60708,-64.93297,0.41504,0.00003,,
8.5408,-1.60939,-65.06196,0.41586,0.00003,,
8.5618,-1.61145,-65.34983,0.4177,0.00003,,
8.5908,-1.61427,-65.04338,0.41574,0.00003,,
8.6198,-1.6172,-65.12096,0.41624,0.00003,,
8.6498,-1.62026,-64.96529,0.41524,0.00003,,
8.6798,-1.62323,-64.9116,0.4149,0.00003,,
8.7078,-1.62596,-65.12473,0.41626,0.00003,,
8.7318,-1.62836,-65.36832,0.41782,0.00003,,
8.7538,-1.63061,-66.20209,0.42315,0.00003,,
8.7768,-1.63291,-66.57005,0.4255,0.00003,,
8.8008,-1.63526,-66.89485,0.42758,0.00003,,
8.8228,-1.6374,-66.95525,0.42796,0.00003,,
8.8568,-1.64085,-66.20991,0.4232,0.00003,,
8.8868,-1.64391,-66.16996,0.42294,0.00003,,
8.9158,-1.6468,-66.60516,0.42572,0.00003,,
8.9478,-1.64994,-66.34346,0.42405,0.00003,,
8.9758,-1.65277,-67.36564,0.43059,0.00003,,
8.9988,-1.65513,-67.50557,0.43148,0.00003,,
9.0278,-1.65805,-67.4265,0.43097,0.00003,,
9.0518,-1.66042,-67.79809,0.43335,0.00003,,
9.0728,-1.6625,-68.19279,0.43587,0.00003,,
9.1028,-1.66556,-68.78022,0.43963,0.00003,,
9.1348,-1.6688,-68.30269,0.43657,0.00003,,
9.1568,-1.67098,-69.20407,0.44234,0.00003,,
9.1838,-1.67362,-69.82265,0.44629,0.00003,,
9.2038,-1.67563,-69.45846,0.44396,0.00003,,
9.2328,-1.67859,-69.33305,0.44316,0.00003,,
9.2598,-1.68127,-69.4409,0.44385,0.00003,,
9.2878,-1.68401,-69.38442,0.44349,0.00003,,
9.3168,-1.68689,-69.74437,0.44579,0.00003,,
9.3478,-1.69004,-69.73995,0.44576,0.00003,,
9.3738,-1.69264,-70.80678,0.45258,0.00003,,
9.4098,-1.69618,-70.82061,0.45267,0.00003,,
9.4408,-1.69924,-71.52376,0.45716,0.00003,,
9.4708,-1.70231,-72.09289,0.4608,0.00003,,
9.5028,-1.70551,-72.81601,0.46542,0.00003,,
9.5288,-1.70805,-74.10166,0.47364,0.00003,,
9.5538,-1.71056,-75.65552,0.48357,0.00003,,
9.5828,-1.71354,-76.74866,0.49056,0.00003,,
9.6078,-1.71604,-77.17106,0.49326,0.00003,,
9.6318,-1.71842,-79.10924,0.50565,0.00003,,
9.6618,-1.72141,-80.59144,0.51512,0.00003,,
9.6958,-1.72487,-82.15625,0.52512,0.00003,,
9.7118,-1.7265,-83.26136,0.53219,0.00003,,
9.7338,-1.72868,-84.85336,0.54236,0.00003,,
9.7568,-1.73094,-86.11046,0.5504,0.00003,,
9.7968,-1.73492,-86.74017,0.55442,0.00003,,
9.8218,-1.73749,-87.74879,0.56087,0.00003,,
9.8488,-1.74018,-88.87285,0.56805,0.00003,,
9.8818,-1.74341,-90.92581,0.58118,0.00003,,
9.9038,-1.74559,-92.03814,0.58829,0.00003,,
9.9338,-1.74864,-93.91611,0.60029,0.00003,,
9.9698,-1.75222,-95.69833,0.61168,0.00003,,
9.9978,-1.75496,-97.4603,0.62294,0.00003,,
10.0238,-1.75753,-98.88709,0.63206,0.00003,,
10.0558,-1.76079,-100.27867,0.64096,0.00003,,
10.0828,-1.76349,-101.00049,0.64557,0.00003,,
10.1138,-1.76655,-103.10132,0.659,0.00003,,
10.1468,-1.76984,-105.28583,0.67296,0.00003,,
10.1728,-1.77251,-106.99905,0.68391,0.00003,,
10.1968,-1.77493,-108.8006,0.69543,0.00003,,
10.2158,-1.7768,-110.58399,0.70683,0.00003,,
10.2448,-1.77965,-111.76225,0.71436,0.00003,,
10.2828,-1.78353,-113.91123,0.72809,0.00003,,
10.3058,-1.78589,-115.53285,0.73846,0.00003,,
10.3298,-1.78824,-116.75153,0.74625,0.00003,,
10.3608,-1.79128,-119.52352,0.76397,0.00003,,
10.3968,-1.79492,-121.32693,0.77549,0.00003,,
10.4198,-1.7973,-122.99134,0.78613,0.00003,,
10.4498,-1.8003,-124.68915,0.79698,0.00003,,
10.4808,-1.80332,-126.92176,0.81125,0.00003,,
10.5098,-1.80621,-128.92238,0.82404,0.00003,,
10.5358,-1.80889,-130.50353,0.83415,0.00003,,
10.5688,-1.81218,-132.95501,0.84982,0.00003,,
10.5928,-1.81449,-134.34952,0.85873,0.00003,,
10.6198,-1.81712,-136.52286,0.87262,0.00003,,
10.6528,-1.8205,-138.40334,0.88464,0.00003,,
10.6818,-1.82342,-140.76442,0.89973,0.00003,,
10.7008,-1.8253,-142.54162,0.91109,0.00003,,
10.7268,-1.82785,-145.05885,0.92718,0.00003,,
10.7508,-1.83025,-146.3572,0.93548,0.00003,,
10.7848,-1.83373,-148.18455,0.94716,0.00003,,
10.8178,-1.83703,-150.14117,0.95967,0.00003,,
10.8398,-1.83916,-151.76465,0.97004,0.00003,,
10.8748,-1.84269,-154.37389,0.98672,0.00003,,
10.8988,-1.84517,-156.32883,0.99922,0.00003,,
10.9318,-1.84848,-158.66756,1.01417,0.00003,,
10.9568,-1.85092,-160.17458,1.0238,0.00003,,
10.9798,-1.85319,-162.74722,1.04024,0.00003,,
11.0068,-1.85597,-164.42491,1.05097,0.00003,,
11.0328,-1.85863,-166.24173,1.06258,0.00003,,
11.0668,-1.86198,-167.70274,1.07192,0.00003,,
11.0958,-1.86479,-170.3491,1.08883,0.00003,,
11.1248,-1.86774,-172.37836,1.1018,0.00003,,
11.1488,-1.8702,-174.46047,1.11511,0.00003,,
11.1858,-1.87383,-176.68437,1.12932,0.00003,,
11.2098,-1.87615,-178.53053,1.14113,0.00003,,
11.2348,-1.87866,-180.9326,1.15648,0.00003,,
11.2628,-1.88152,-183.06072,1.17008,0.00003,,
11.2948,-1.88468,-185.41818,1.18515,0.00003,,
11.3188,-1.88701,-186.73572,1.19357,0.00003,,
11.3458,-1.88971,-188.81387,1.20685,0.00003,,
11.3738,-1.8926,-191.18111,1.22198,0.00003,,
11.3988,-1.8951,-192.97898,1.23348,0.00003,,
11.4288,-1.89807,-195.4197,1.24908,0.00003,,
11.4648,-1.90164,-198.06535,1.26599,0.00003,,
11.4888,-1.90409,-200.05256,1.27869,0.00003,,
11.5088,-1.90611,-202.5309,1.29453,0.00003,,
11.5358,-1.90882,-203.60602,1.3014,0.00003,,
11.5618,-1.91138,-205.51072,1.31358,0.00003,,
11.5908,-1.91429,-207.6664,1.32735,0.00003,,
11.6078,-1.91604,-208.62655,1.33349,0.00003,,
11.6378,-1.91908,-210.09129,1.34285,0.00003,,
11.6688,-1.92213,-212.28031,1.35685,0.00003,,
11.6928,-1.9245,-214.55591,1.37139,0.00003,,
11.7198,-1.92725,-216.75825,1.38547,0.00003,,
11.7498,-1.93028,-218.94742,1.39946,0.00003,,
11.7888,-1.93412,-221.32508,1.41466,0.00003,,
11.8108,-1.93629,-223.9014,1.43113,0.00003,,
11.8338,-1.93861,-226.28964,1.44639,0.00003,,
11.8658,-1.94185,-227.75223,1.45574,0.00003,,
11.8918,-1.94444,-230.58942,1.47387,0.00003,,
11.9248,-1.94766,-233.02273,1.48943,0.00003,,
11.9528,-1.95048,-235.47504,1.5051,0.00003,,
11.9768,-1.95292,-238.08093,1.52176,0.00003,,
12.0008,-1.9553,-240.01389,1.53411,0.00003,,
12.0338,-1.95853,-242.14014,1.5477,0.00003,,
12.0638,-1.96157,-244.16256,1.56063,0.00003,,
12.0878,-1.96403,-246.28178,1.57418,0.00003,,
12.1138,-1.96662,-249.00381,1.59157,0.00003,,
12.1398,-1.9692,-250.89844,1.60368,0.00003,,
12.1678,-1.97199,-253.55187,1.62064,0.00003,,
12.1928,-1.97455,-256.18807,1.63749,0.00003,,
12.2158,-1.97689,-258.13468,1.64994,0.00003,,
12.2428,-1.97957,-260.2241,1.66329,0.00003,,
12.2658,-1.98185,-262.3911,1.67714,0.00003,,
12.2998,-1.98526,-265.04388,1.6941,0.00003,,
12.3368,-1.98901,-268.05243,1.71333,0.00003,,
12.3728,-1.99255,-271.20523,1.73348,0.00003,,
12.4028,-1.9955,-274.75604,1.75618,0.00003,,
12.4278,-1.99803,-277.44658,1.77337,0.00003,,
12.4558,-2.00085,-280.74775,1.79447,0.00003,,
12.4868,-2.0039,-283.06819,1.80931,0.00003,,
12.5178,-2.00693,-285.61018,1.82555,0.00003,,
12.5518,-2.01038,-289.05291,1.84756,0.00003,,
12.5798,-2.0132,-292.7538,1.87121,0.00003,,
12.6028,-2.01548,-295.3588,1.88786,0.00003,,
12.6438,-2.01951,-298.43966,1.90756,0.00003,,
12.6928,-2.02453,-303.17488,1.93782,0.00003,,
12.7268,-2.02788,-307.83727,1.96762,0.00003,,
12.7478,-2.02995,-310.17498,1.98257,0.00003,,
12.7738,-2.03259,-313.4496,2.0035,0.00003,,
12.7988,-2.03518,-315.88417,2.01906,0.00003,,
12.8228,-2.03757,-318.56652,2.0362,0.00003,,
12.8648,-2.04169,-321.63388,2.05581,0.00003,,
12.8908,-2.04431,-324.69924,2.0754,0.00003,,
12.9328,-2.04859,-328.9877,2.10281,0.00003,,
12.9558,-2.05087,-332.0579,2.12244,0.00003,,
12.9808,-2.0533,-334.95082,2.14093,0.00003,,
13.0028,-2.05549,-337.66543,2.15828,0.00003,,
13.0298,-2.05827,-340.17344,2.17431,0.00003,,
13.0568,-2.061,-342.64722,2.19012,0.00003,,
13.0818,-2.06345,-345.54959,2.20867,0.00003,,
13.1068,-2.06585,-348.17392,2.22545,0.00003,,
13.1328,-2.06845,-350.34725,2.23934,0.00003,,
13.1558,-2.07082,-353.4988,2.25948,0.00003,,
13.1818,-2.07343,-355.88299,2.27472,0.00003,,
13.2078,-2.07599,-358.4784,2.29131,0.00003,,
13.2308,-2.07824,-360.60507,2.3049,0.00003,,
13.2528,-2.08045,-363.22311,2.32164,0.00003,,
13.2808,-2.08333,-365.7924,2.33806,0.00003,,
13.3068,-2.08594,-368.63326,2.35622,0.00003,,
13.3278,-2.08799,-370.77465,2.3699,0.00003,,
13.3488,-2.09003,-373.44601,2.38698,0.00003,,
13.3758,-2.09277,-376.13856,2.40419,0.00003,,
13.3998,-2.09527,-378.67646,2.42041,0.00003,,
13.4288,-2.09816,-381.2863,2.43709,0.00003,,
13.4648,-2.10169,-384.63962,2.45853,0.00003,,
13.4908,-2.10431,-387.90791,2.47942,0.00003,,
13.5128,-2.10659,-390.63715,2.49686,0.00003,,
13.5328,-2.10862,-393.59392,2.51576,0.00003,,
13.5618,-2.11148,-396.16982,2.53222,0.00003,,
13.5948,-2.1147,-399.25189,2.55192,0.00003,,
13.6118,-2.11642,-401.25437,2.56472,0.00003,,
13.6478,-2.12011,-404.55605,2.58583,0.00003,,
13.6788,-2.12317,-408.11612,2.60858,0.00003,,
13.7108,-2.12626,-411.14823,2.62796,0.00003,,
13.7378,-2.12898,-414.56912,2.64983,0.00003,,
13.7708,-2.13232,-418.0219,2.6719,0.00003,,
13.7978,-2.13498,-421.50654,2.69417,0.00003,,
13.8198,-2.13712,-423.95894,2.70985,0.00003,,
13.8518,-2.14034,-426.91668,2.72875,0.00003,,
13.8758,-2.14281,-429.37407,2.74446,0.00003,,
13.8988,-2.1451,-432.42369,2.76395,0.00003,,
13.9318,-2.14836,-435.82572,2.7857,0.00003,,
13.9668,-2.15185,-439.08586,2.80653,0.00003,,
13.9998,-2.15523,-442.75047,2.82996,0.00003,,
14.0208,-2.15734,-445.7016,2.84882,0.00003,,
14.0548,-2.1607,-449.35551,2.87217,0.00003,,
14.0788,-2.1631,-452.25006,2.89068,0.00003,,
14.1148,-2.16678,-455.7929,2.91332,0.00003,,
14.1538,-2.17068,-459.98651,2.94013,0.00003,,
14.1758,-2.17282,-463.36404,2.96171,0.00003,,
14.2048,-2.17571,-467.1501,2.98591,0.00003,,
14.2298,-2.17826,-470.49765,3.00731,0.00003,,
14.2578,-2.18107,-473.70717,3.02782,0.00003,,
14.2838,-2.18363,-476.64158,3.04658,0.00003,,
14.3068,-2.18587,-479.9006,3.06741,0.00003,,
14.3308,-2.18829,-483.65807,3.09143,0.00003,,
14.3558,-2.19083,-486.08733,3.10696,0.00003,,
14.3858,-2.19382,-490.09211,3.13255,0.00003,,
14.4068,-2.19587,-492.44761,3.14761,0.00003,,
14.4308,-2.19824,-495.97984,3.17019,0.00003,,
14.4548,-2.20067,-499.39966,3.19205,0.00003,,
14.4788,-2.20312,-502.29235,3.21053,0.00003,,
14.5048,-2.20571,-505.26927,3.22956,0.00003,,
14.5398,-2.20915,-508.97817,3.25327,0.00003,,
14.5808,-2.21333,-514.18119,3.28653,0.00003,,
14.6078,-2.21604,-517.5841,3.30828,0.00003,,
14.6358,-2.21882,-522.14768,3.33745,0.00003,,
14.6748,-2.2227,-526.05867,3.36244,0.00003,,
14.6988,-2.22517,-529.93926,3.38725,0.00003,,
14.7228,-2.22758,-533.14213,3.40772,0.00003,,
14.7558,-2.23084,-535.06643,3.42002,0.00003,,
14.7808,-2.23332,-535.7834,3.4246,0.00003,,
14.8048,-2.23574,-538.07879,3.43927,0.00003,,
14.8368,-2.23899,-541.639,3.46203,0.00003,,
14.8678,-2.24205,-545.46124,3.48646,0.00003,,
14.8958,-2.24479,-548.52134,3.50602,0.00003,,
14.9198,-2.24721,-552.38279,3.5307,0.00003,,
14.9538,-2.25068,-556.93686,3.55981,0.00003,,
14.9788,-2.25315,-560.5523,3.58292,0.00003,,
15.0138,-2.25656,-565.22461,3.61278,0.00003,,
15.0428,-2.25947,-570.01854,3.64342,0.00003,,
15.0698,-2.26221,-574.10197,3.66952,0.00003,,
15.0968,-2.26488,-577.88305,3.69369,0.00003,,
15.1198,-2.26715,-581.64648,3.71775,0.00003,,
15.1478,-2.26993,-585.68744,3.74358,0.00003,,
15.1768,-2.27291,-590.04193,3.77141,0.00003,,
15.1958,-2.27482,-593.35637,3.79259,0.00003,,
15.2178,-2.27698,-596.82829,3.81479,0.00003,,
15.2478,-2.27994,-600.67307,3.83936,0.00003,,
15.2898,-2.28424,-606.38492,3.87587,0.00003,,
15.3138,-2.28668,-610.66812,3.90325,0.00003,,
15.3348,-2.28875,-614.2803,3.92633,0.00003,,
15.3638,-2.29159,-619.24271,3.95805,0.00003,,
15.4008,-2.29535,-623.65881,3.98628,0.00003,,
15.4238,-2.29771,-627.94192,4.01366,0.00003,,
15.4548,-2.30076,-632.90396,4.04537,0.00003,,
15.4838,-2.3036,-637.30911,4.07353,0.00003,,
15.5058,-2.30579,-640.34476,4.09293,0.00003,,
15.5368,-2.30897,-645.4749,4.12572,0.00003,,
15.5648,-2.31177,-649.50753,4.1515,0.00003,,
15.5948,-2.31468,-654.33253,4.18234,0.00003,,
15.6198,-2.31712,-658.07137,4.20624,0.00003,,
15.6438,-2.31956,-662.55648,4.23491,0.00003,,
15.6678,-2.32201,-666.51357,4.2602,0.00003,,
15.6938,-2.32461,-670.40916,4.2851,0.00003,,
15.7198,-2.32716,-673.81831,4.30689,0.00003,,
15.7488,-2.33006,-678.8935,4.33933,0.00003,,
15.7758,-2.33282,-682.33232,4.36131,0.00003,,
15.8018,-2.33544,-686.80556,4.3899,0.00003,,
15.8298,-2.3382,-691.18035,4.41786,0.00003,,
15.8528,-2.34046,-695.01405,4.44237,0.00003,,
15.8848,-2.34372,-700.03942,4.47449,0.00003,,
15.9088,-2.34618,-704.44751,4.50266,0.00003,,
15.9348,-2.34877,-707.84846,4.5244,0.00003,,
15.9598,-2.3512,-711.88393,4.55019,0.00003,,
15.9798,-2.35318,-715.44135,4.57293,0.00003,,
16.0088,-2.35617,-719.71249,4.60023,0.00003,,
16.0368,-2.359,-723.86786,4.62679,0.00003,,
16.0638,-2.36166,-728.00661,4.65325,0.00003,,
16.0968,-2.36489,-733.36437,4.68749,0.00003,,
16.1158,-2.36683,-736.56025,4.70792,0.00003,,
16.1428,-2.36961,-740.85556,4.73537,0.00003,,
16.1738,-2.3727,-745.20297,4.76316,0.00003,,
16.2148,-2.37669,-750.77307,4.79877,0.00003,,
16.2438,-2.37962,-755.35206,4.82803,0.00003,,
16.2728,-2.38255,-760.8186,4.86297,0.00003,,
16.2958,-2.38482,-764.51818,4.88662,0.00003,,
16.3218,-2.38735,-768.7727,4.91381,0.00003,,
16.3488,-2.39006,-772.65808,4.93865,0.00003,,
16.3738,-2.39262,-776.66822,4.96428,0.00003,,
16.3958,-2.39482,-781.33447,4.99411,0.00003,,
16.4178,-2.39701,-785.34698,5.01975,0.00003,,
16.4518,-2.40037,-789.05467,5.04345,0.00003,,
16.4728,-2.4025,-792.70555,5.06679,0.00003,,
16.5,-2.40526,-797.60058,5.09808,0.00003,,
16.5258,-2.40786,-801.03334,5.12002,0.00003,,
16.5498,-2.41022,-805.64059,5.14947,0.00003,,
16.5748,-2.41269,-809.67778,5.17527,0.00003,,
16.6,-2.41525,-813.3146,5.19852,0.00003,,
16.6318,-2.4185,-817.99543,5.22843,0.00003,,
16.6668,-2.42196,-824.64674,5.27095,0.00003,,
16.6948,-2.42472,-828.27853,5.29416,0.00003,,
16.7218,-2.42748,-833.30274,5.32628,0.00003,,
16.7488,-2.43021,-837.77364,5.35485,0.00003,,
16.7738,-2.43268,-842.1259,5.38267,0.00003,,
16.8018,-2.43539,-846.25399,5.40906,0.00003,,
16.8368,-2.43892,-851.64309,5.4435,0.00003,,
16.8718,-2.44245,-857.77463,5.48269,0.00003,,
16.8998,-2.4452,-862.83237,5.51502,0.00003,,
16.9218,-2.44735,-866.6818,5.53963,0.00003,,
16.9468,-2.44986,-871.22666,5.56868,0.00003,,
16.9748,-2.45273,-875.60993,5.59669,0.00003,,
17.0018,-2.45543,-880.57844,5.62845,0.00003,,
17.0198,-2.4572,-883.82177,5.64918,0.00003,,
17.0428,-2.45948,-887.56783,5.67312,0.00003,,
17.0648,-2.46171,-891.51645,5.69836,0.00003,,
17.0908,-2.46437,-896.04119,5.72728,0.00003,,
17.1188,-2.46715,-899.46575,5.74917,0.00003,,
17.1508,-2.47033,-903.88758,5.77744,0.00003,,
17.1758,-2.47284,-908.42983,5.80647,0.00003,,
17.2008,-2.47541,-912.87689,5.83489,0.00003,,
17.2218,-2.47751,-916.18625,5.85605,0.00003,,
17.2418,-2.4795,-917.12391,5.86204,0.00003,,
17.2718,-2.48245,-915.46159,5.85142,0.00003,,
17.2898,-2.48424,-916.76842,5.85977,0.00003,,
17.3238,-2.48773,-921.50616,5.89005,0.00003,,
17.3488,-2.49021,-926.18726,5.91997,0.00003,,
17.3698,-2.49227,-930.01788,5.94446,0.00003,,
17.4,-2.4952,-934.51813,5.97322,0.00003,,
17.4368,-2.49896,-940.20488,6.00957,0.00003,,
17.4588,-2.50116,-944.75234,6.03863,0.00003,,
17.4828,-2.50352,-948.93724,6.06538,0.00003,,
17.5088,-2.50606,-953.43469,6.09413,0.00003,,
17.5338,-2.50855,-957.3767,6.11933,0.00003,,
17.5718,-2.51241,-964.0296,6.16185,0.00003,,
17.6138,-2.51658,-970.79761,6.20511,0.00003,,
17.6418,-2.51935,-976.03071,6.23856,0.00003,,
17.6668,-2.5219,-981.35499,6.27259,0.00003,,
17.6898,-2.52426,-985.70986,6.30043,0.00003,,
17.7118,-2.52644,-989.83832,6.32681,0.00003,,
17.7338,-2.52859,-993.98773,6.35334,0.00003,,
17.7638,-2.53158,-998.96062,6.38512,0.00003,,
17.7948,-2.5348,-1004.15265,6.41831,0.00003,,
17.8198,-2.5373,-1009.11548,6.45003,0.00003,,
17.8458,-2.53984,-1013.8493,6.48029,0.00003,,
17.8698,-2.5422,-1019.21093,6.51456,0.00003,,
17.8918,-2.54443,-1022.95494,6.53849,0.00003,,
17.9158,-2.54691,-1026.865,6.56348,0.00003,,
17.9378,-2.54912,-1031.13959,6.5908,0.00003,,
17.9708,-2.55237,-1036.90624,6.62766,0.00003,,
17.9978,-2.55501,-1041.06357,6.65423,0.00003,,
18.0208,-2.55735,-1045.54333,6.68287,0.00003,,
18.0528,-2.56061,-1052.14817,6.72508,0.00003,,
18.0968,-2.5649,-1058.71204,6.76704,0.00003,,
18.1158,-2.56675,-1062.7253,6.79269,0.00003,,
18.1428,-2.56949,-1068.84539,6.83181,0.00003,,
18.1668,-2.57195,-1073.59327,6.86216,0.00003,,
18.1898,-2.57422,-1078.0517,6.89065,0.00003,,
18.2118,-2.57639,-1082.47502,6.91893,0.00003,,
18.2428,-2.57946,-1087.33214,6.94997,0.00003,,
18.2658,-2.5818,-1092.17213,6.98091,0.00003,,
18.2978,-2.58505,-1098.72567,7.0228,0.00003,,
18.3158,-2.58684,-1101.68532,7.04171,0.00003,,
18.3558,-2.59074,-1108.81552,7.08729,0.00003,,
18.3788,-2.5931,-1113.81104,7.11922,0.00003,,
18.4128,-2.5966,-1120.44346,7.16161,0.00003,,
18.4488,-2.60014,-1127.04784,7.20382,0.00003,,
18.4838,-2.60362,-1133.42563,7.24459,0.00003,,
18.5098,-2.60631,-1139.16649,7.28128,0.00003,,
18.5368,-2.60905,-1145.03587,7.3188,0.00003,,
18.5808,-2.61335,-1152.09213,7.3639,0.00003,,
18.6078,-2.61602,-1157.49743,7.39845,0.00003,,
18.6398,-2.6193,-1164.62735,7.44402,0.00003,,
18.6738,-2.6227,-1171.02601,7.48492,0.00003,,
18.6898,-2.62425,-1158.57543,7.40534,0.00003,,
18.7038,-2.6256,-1121.8817,7.1708,0.00003,,
18.7188,-2.62708,-1088.73742,6.95895,0.00003,,
18.7338,-2.6286,-1072.08863,6.85254,0.00003,,
18.7488,-2.63015,-1067.57097,6.82366,0.00003,,
18.7638,-2.63167,-1068.61806,6.83036,0.00003,,
18.7818,-2.63344,-1071.99289,6.85193,0.00003,,
18.8158,-2.63675,-1074.08864,6.86532,0.00003,,
18.8498,-2.64016,-1077.20029,6.88521,0.00003,,
18.8858,-2.64383,-1077.41905,6.88661,0.00003,,
18.9128,-2.64651,-1080.19803,6.90437,0.00003,,
18.9498,-2.65016,-1084.14041,6.92957,0.00003,,
18.9878,-2.65403,-1087.19505,6.9491,0.00003,,
19.0108,-2.65636,-1090.27838,6.9688,0.00003,,
19.0408,-2.65937,-1093.77876,6.99118,0.00003,,
19.0628,-2.66152,-1095.91056,7.0048,0.00003,,
19.0978,-2.66505,-1099.26742,7.02626,0.00003,,
19.1188,-2.6672,-1102.1073,7.04441,0.00003,,
19.1408,-2.6694,-1057.80326,6.76123,0.00003,,
19.1558,-2.6709,-901.88505,5.76464,0.00003,,
19.1708,-2.67241,-772.98051,4.94071,0.00003,,
19.1858,-2.67392,-713.34299,4.55952,0.00003,,
19.2,-2.67534,-695.00394,4.4423,0.00003,,
19.2148,-2.67686,-697.6991,4.45953,0.00003,,
19.2298,-2.67837,-703.43758,4.49621,0.00003,,
19.2448,-2.67986,-708.33014,4.52748,0.00003,,
19.2598,-2.68133,-710.79764,4.54325,0.00003,,
19.2748,-2.6828,-711.77869,4.54952,0.00003,,
19.2898,-2.68426,-712.45804,4.55386,0.00003,,
19.3038,-2.68563,-713.12794,4.55815,0.00003,,
19.3188,-2.68713,-713.96492,4.5635,0.00003,,
19.3338,-2.68865,-714.60139,4.56756,0.00003,,
19.3488,-2.69017,-714.9809,4.56999,0.00003,,
19.3638,-2.69168,-715.34854,4.57234,0.00003,,
19.3788,-2.69317,-716.09886,4.57714,0.00003,,
19.3938,-2.69465,-717.09454,4.5835,0.00003,,
19.4078,-2.69601,-718.0226,4.58943,0.00003,,
19.4228,-2.69748,-719.17493,4.5968,0.00003,,
19.4378,-2.69897,-720.38597,4.60454,0.00003,,
19.4528,-2.7005,-721.56163,4.61205,0.00003,,
19.4678,-2.70204,-722.552,4.61838,0.00003,,
19.4828,-2.70355,-723.88598,4.62691,0.00003,,
19.4978,-2.70505,-725.08617,4.63458,0.00003,,
19.5158,-2.70683,-726.11161,4.64113,0.00003,,
19.5508,-2.71027,-726.7049,4.64493,0.00003,,
19.5758,-2.71283,-728.65239,4.65737,0.00003,,
19.6058,-2.71584,-731.44711,4.67524,0.00003,,
19.6358,-2.71883,-733.5173,4.68847,0.00003,,
19.6608,-2.72131,-735.56653,4.70157,0.00003,,
19.6818,-2.72343,-738.16506,4.71818,0.00003,,
19.7128,-2.72661,-740.25239,4.73152,0.00003,,
19.7458,-2.7299,-741.83568,4.74164,0.00003,,
19.7748,-2.73275,-744.5754,4.75915,0.00003,,
19.8018,-2.73547,-747.36844,4.777,0.00003,,
19.8248,-2.73784,-749.96143,4.79358,0.00003,,
19.8608,-2.74142,-750.8833,4.79947,0.00003,,
19.8888,-2.74416,-753.22054,4.81441,0.00003,,
19.9088,-2.74614,-755.29017,4.82764,0.00003,,
19.9348,-2.74878,-755.32468,4.82786,0.00003,,
19.9618,-2.75148,-752.73584,4.81131,0.00003,,
19.9938,-2.75461,-752.92327,4.81251,0.00003,,
20.0278,-2.75796,-754.95522,4.8255,0.00003,,
20.0528,-2.7605,-757.28721,4.8404,0.00003,,
20.0778,-2.76301,-759.3614,4.85366,0.00003,,
20.1128,-2.76646,-761.68552,4.86852,0.00003,,
20.1378,-2.76893,-763.83022,4.88222,0.00003,,
20.1628,-2.77148,-766.45962,4.89903,0.00003,,
20.1848,-2.77375,-768.65549,4.91307,0.00003,,
20.2058,-2.77583,-770.32559,4.92374,0.00003,,
20.2388,-2.77908,-772.39964,4.937,0.00003,,
20.2618,-2.78139,-774.37256,4.94961,0.00003,,
20.2928,-2.78459,-776.39045,4.96251,0.00003,,
20.3198,-2.78731,-778.06013,4.97318,0.00003,,
20.3508,-2.79035,-780.41353,4.98822,0.00003,,
20.3748,-2.79271,-781.74891,4.99676,0.00003,,
20.3968,-2.79495,-780.59193,4.98936,0.00003,,
20.4218,-2.79752,-775.4623,4.95657,0.00003,,
20.4438,-2.79971,-775.35454,4.95588,0.00003,,
20.4628,-2.80158,-777.21989,4.96781,0.00003,,
20.4898,-2.80421,-780.17781,4.98671,0.00003,,
20.5118,-2.80643,-782.02998,4.99855,0.00003,,
20.5318,-2.80849,-784.29421,5.01302,0.00003,,
20.5628,-2.8116,-785.91211,5.02337,0.00003,,
20.5868,-2.81393,-787.45522,5.03323,0.00003,,
20.6038,-2.81557,-781.22998,4.99344,0.00003,,
20.6308,-2.81826,-772.83937,4.93981,0.00003,,
20.6558,-2.82084,-772.28807,4.93628,0.00003,,
20.6788,-2.82315,-774.48003,4.95029,0.00003,,
20.7098,-2.8262,-776.88913,4.96569,0.00003,,
20.7378,-2.82897,-778.074,4.97327,0.00003,,
20.7638,-2.83162,-780.45796,4.9885,0.00003,,
20.7908,-2.83438,-782.90682,5.00416,0.00003,,
20.8178,-2.83707,-784.65492,5.01533,0.00003,,
20.8438,-2.83959,-786.76855,5.02884,0.00003,,
20.8688,-2.84208,-789.194,5.04434,0.00003,,
20.9018,-2.84549,-791.09361,5.05648,0.00003,,
20.9278,-2.84808,-793.27384,5.07042,0.00003,,
20.9508,-2.85034,-795.38217,5.0839,0.00003,,
20.9768,-2.8529,-797.6627,5.09847,0.00003,,
21.0018,-2.85546,-799.42364,5.10973,0.00003,,
21.0278,-2.85813,-801.62706,5.12381,0.00003,,
21.0518,-2.86053,-803.5332,5.136,0.00003,,
21.0798,-2.86325,-805.79603,5.15046,0.00003,,
21.1048,-2.86572,-807.37285,5.16054,0.00003,,
21.1378,-2.8691,-809.82475,5.17621,0.00003,,
21.1588,-2.87121,-812.2921,5.19198,0.00003,,
21.1828,-2.87357,-814.31838,5.20493,0.00003,,
21.2078,-2.87599,-816.37669,5.21809,0.00003,,
21.2438,-2.87961,-817.65307,5.22625,0.00003,,
21.2678,-2.88205,-819.89188,5.24056,0.00003,,
21.2918,-2.88441,-822.22046,5.25544,0.00003,,
21.3228,-2.88743,-824.14635,5.26775,0.00003,,
21.3558,-2.89077,-826.18231,5.28076,0.00003,,
21.3848,-2.89373,-828.43695,5.29517,0.00003,,
21.4058,-2.89581,-830.5179,5.30848,0.00003,,
21.4278,-2.89799,-832.71349,5.32251,0.00003,,
21.4508,-2.90025,-834.26945,5.33245,0.00003,,
21.4708,-2.90227,-835.89926,5.34287,0.00003,,
21.4998,-2.90524,-837.35976,5.35221,0.00003,,
21.5218,-2.90746,-838.59488,5.3601,0.00003,,
21.5528,-2.91054,-841.25753,5.37712,0.00003,,
21.5738,-2.91262,-842.7958,5.38695,0.00003,,
21.6068,-2.916,-844.96336,5.40081,0.00003,,
21.6478,-2.92013,-844.12871,5.39547,0.00003,,
21.6628,-2.9216,-824.49866,5.27,0.00003,,
21.6778,-2.92307,-805.74378,5.15013,0.00003,,
21.6948,-2.92475,-795.15399,5.08244,0.00003,,
21.7138,-2.92668,-792.30582,5.06423,0.00003,,
21.7428,-2.92963,-794.19557,5.07631,0.00003,,
21.7728,-2.9326,-796.39414,5.09036,0.00003,,
21.7978,-2.93503,-797.0823,5.09476,0.00003,,
21.8178,-2.93701,-798.55025,5.10415,0.00003,,
21.8508,-2.94036,-800.21983,5.11482,0.00003,,
21.8768,-2.94294,-801.64783,5.12394,0.00003,,
21.8958,-2.94481,-802.85361,5.13165,0.00003,,
21.9178,-2.94695,-803.36249,5.1349,0.00003,,
21.9398,-2.94914,-803.94456,5.13862,0.00003,,
21.9628,-2.95149,-804.99146,5.14532,0.00003,,
21.9938,-2.95463,-805.94616,5.15142,0.00003,,
22.0128,-2.95652,-807.25383,5.15978,0.00003,,
22.0338,-2.95859,-801.10803,5.12049,0.00003,,
22.0488,-2.96008,-776.73285,4.96469,0.00003,,
22.0638,-2.96161,-756.79631,4.83726,0.00003,,
22.0788,-2.96315,-746.08373,4.76879,0.00003,,
22.0978,-2.96509,-741.77063,4.74122,0.00003,,
22.1228,-2.96758,-740.53505,4.73333,0.00003,,
22.1498,-2.97026,-740.43106,4.73266,0.00003,,
22.1748,-2.97276,-741.37603,4.7387,0.00003,,
22.1948,-2.9748,-742.7556,4.74752,0.00003,,
22.2178,-2.97714,-743.73214,4.75376,0.00003,,
22.2418,-2.97952,-744.37279,4.75786,0.00003,,
22.2758,-2.98285,-745.32344,4.76393,0.00003,,
22.3048,-2.98577,-746.21006,4.7696,0.00003,,
22.3368,-2.98903,-747.18348,4.77582,0.00003,,
22.3598,-2.99129,-746.9228,4.77416,0.00003,,
22.3858,-2.99382,-745.32204,4.76392,0.00003,,
22.4068,-2.99591,-745.70565,4.76638,0.00003,,
22.4278,-2.99805,-746.69998,4.77273,0.00003,,
22.4538,-3.00069,-747.56783,4.77828,0.00003,,
22.4848,-3.00373,-748.70302,4.78553,0.00003,,
22.5138,-3.00658,-749.84478,4.79283,0.00003,,
22.5418,-3.00938,-750.86993,4.79938,0.00003,,
22.5648,-3.01173,-752.49085,4.80974,0.00003,,
22.5878,-3.01401,-753.72169,4.81761,0.00003,,
22.6138,-3.01658,-755.49209,4.82893,0.00003,,
22.6388,-3.01905,-755.92902,4.83172,0.00003,,
22.6658,-3.0218,-756.79435,4.83725,0.00003,,
22.6878,-3.02407,-757.68023,4.84291,0.00003,,
22.7178,-3.02704,-758.92033,4.85084,0.00003,,
22.7528,-3.03048,-758.50845,4.84821,0.00003,,
22.7848,-3.03376,-757.11966,4.83933,0.00003,,
22.8118,-3.03652,-756.46411,4.83514,0.00003,,
22.8368,-3.03897,-757.7525,4.84338,0.00003,,
22.8598,-3.0412,-758.31995,4.847,0.00003,,
22.8878,-3.04401,-758.31562,4.84698,0.00003,,
22.9228,-3.04764,-757.81639,4.84378,0.00003,,
22.9468,-3.05003,-758.32373,4.84703,0.00003,,
22.9718,-3.05249,-758.82436,4.85023,0.00003,,
22.9938,-3.05464,-758.68899,4.84936,0.00003,,
23.0178,-3.05705,-758.80596,4.85011,0.00003,,
23.0458,-3.05991,-758.99051,4.85129,0.00003,,
23.0678,-3.0621,-758.85858,4.85045,0.00003,,
23.0888,-3.06414,-758.97556,4.85119,0.00003,,
23.1138,-3.06656,-758.62035,4.84892,0.00003,,
23.1378,-3.06898,-757.78435,4.84358,0.00003,,
23.1588,-3.07114,-758.3621,4.84727,0.00003,,
23.1818,-3.07346,-758.84028,4.85033,0.00003,,
23.2008,-3.07534,-758.9356,4.85094,0.00003,,
23.2278,-3.07798,-758.3675,4.84731,0.00003,,
23.2538,-3.08058,-756.88716,4.83784,0.00003,,
23.2808,-3.08335,-756.81782,4.8374,0.00003,,
23.3058,-3.08586,-757.17876,4.83971,0.00003,,
23.3388,-3.0891,-755.64561,4.82991,0.00003,,
23.3668,-3.0919,-755.44096,4.8286,0.00003,,
23.3908,-3.09439,-756.67342,4.83648,0.00003,,
23.4098,-3.09633,-758.0223,4.8451,0.00003,,
23.4388,-3.09922,-758.25029,4.84656,0.00003,,
23.4648,-3.10175,-759.44406,4.85419,0.00003,,
23.4948,-3.10476,-760.22544,4.85918,0.00003,,
23.5188,-3.10724,-760.48584,4.86085,0.00003,,
23.5428,-3.10966,-756.63654,4.83624,0.00003,,
23.5658,-3.11191,-753.85645,4.81847,0.00003,,
23.5858,-3.11383,-753.45752,4.81592,0.00003,,
23.6118,-3.11643,-753.14571,4.81393,0.00003,,
23.6478,-3.12012,-752.86808,4.81216,0.00003,,
23.6798,-3.12328,-754.22325,4.82082,0.00003,,
23.7038,-3.1256,-754.82694,4.82468,0.00003,,
23.7358,-3.12878,-755.17884,4.82693,0.00003,,
23.7638,-3.13164,-755.32282,4.82785,0.00003,,
23.7978,-3.135,-756.42406,4.83488,0.00003,,
23.8378,-3.13893,-755.18233,4.82695,0.00003,,
23.8548,-3.14067,-742.95457,4.74879,0.00003,,
23.8698,-3.14222,-707.96525,4.52515,0.00003,,
23.8848,-3.14375,-680.33086,4.34852,0.00003,,
23.8998,-3.14525,-666.25932,4.25857,0.00003,,
23.9138,-3.14665,-661.29221,4.22682,0.00003,,
23.9288,-3.14812,-660.3362,4.22071,0.00003,,
23.9518,-3.15038,-660.24531,4.22013,0.00003,,
23.9718,-3.15239,-659.42588,4.2149,0.00003,,
23.9938,-3.15464,-659.10802,4.21286,0.00003,,
24.0188,-3.15716,-658.40995,4.2084,0.00003,,
24.0438,-3.15964,-657.98271,4.20567,0.00003,,
24.0678,-3.16201,-658.72911,4.21044,0.00003,,
24.1128,-3.1666,-657.03234,4.1996,0.00003,,
24.1338,-3.16872,-656.88812,4.19867,0.00003,,
24.1578,-3.17111,-657.86391,4.20491,0.00003,,
24.1798,-3.17326,-658.45978,4.20872,0.00003,,
24.2078,-3.17604,-657.98089,4.20566,0.00003,,
24.2288,-3.17818,-658.42732,4.20851,0.00003,,
24.2528,-3.18059,-659.2338,4.21367,0.00003,,
24.2748,-3.18276,-659.63562,4.21624,0.00003,,
24.2978,-3.18499,-660.05806,4.21894,0.00003,,
24.3278,-3.18798,-659.52213,4.21551,0.00003,,
24.3558,-3.19084,-658.92083,4.21167,0.00003,,
24.3968,-3.19492,-659.02811,4.21235,0.00003,,
24.4278,-3.19795,-660.38794,4.22104,0.00003,,
24.4548,-3.20067,-661.03437,4.22518,0.00003,,
24.4778,-3.20302,-661.81435,4.23016,0.00003,,
24.5008,-3.20532,-662.21501,4.23272,0.00003,,
24.5268,-3.2079,-663.15671,4.23874,0.00003,,
24.5578,-3.21099,-662.52099,4.23468,0.00003,,
24.5778,-3.21305,-662.59033,4.23512,0.00003,,
24.6088,-3.21615,-663.18507,4.23892,0.00003,,
24.6338,-3.21863,-663.61707,4.24168,0.00003,,
24.6558,-3.22081,-663.65907,4.24195,0.00003,,
24.6868,-3.22395,-663.55341,4.24128,0.00003,,
24.7148,-3.22682,-664.10438,4.2448,0.00003,,
24.7538,-3.23069,-663.57595,4.24142,0.00003,,
24.7838,-3.23366,-664.58168,4.24785,0.00003,,
24.8028,-3.23559,-665.3612,4.25283,0.00003,,
24.8238,-3.23775,-666.02067,4.25705,0.00003,,
24.8488,-3.24022,-666.12898,4.25774,0.00003,,
24.8778,-3.24307,-665.62542,4.25452,0.00003,,
24.9088,-3.24613,-665.69876,4.25499,0.00003,,
24.9328,-3.24857,-666.52605,4.26028,0.00003,,
24.9568,-3.251,-667.13355,4.26416,0.00003,,
24.9848,-3.25376,-666.79711,4.26201,0.00003,,
25.0138,-3.25658,-666.17373,4.25803,0.00003,,
25.0438,-3.25958,-666.39134,4.25942,0.00003,,
25.0718,-3.26243,-666.59492,4.26072,0.00003,,
25.1038,-3.2656,-666.20437,4.25822,0.00003,,
25.1258,-3.26776,-665.91608,4.25638,0.00003,,
25.1548,-3.27066,-664.43849,4.24693,0.00003,,
25.1848,-3.27375,-663.58075,4.24145,0.00003,,
25.2028,-3.27555,-663.27597,4.2395,0.00003,,
25.2268,-3.27792,-662.902,4.23711,0.00003,,
25.2508,-3.2803,-662.20546,4.23266,0.00003,,
25.2828,-3.28356,-661.40294,4.22753,0.00003,,
25.3108,-3.28642,-660.67246,4.22286,0.00003,,
25.3388,-3.28918,-659.87115,4.21774,0.00003,,
25.3638,-3.29163,-659.17852,4.21331,0.00003,,
25.4,-3.29527,-657.4125,4.20203,0.00003,,
25.4198,-3.29732,-657.04421,4.19967,0.00003,,
25.4458,-3.29991,-655.95508,4.19271,0.00003,,
25.4748,-3.30275,-653.9464,4.17987,0.00003,,
25.5,-3.30521,-651.79439,4.16612,0.00003,,
25.5228,-3.30755,-650.37492,4.15704,0.00003,,
25.5498,-3.31031,-648.34789,4.14409,0.00003,,
25.5718,-3.31249,-647.26397,4.13716,0.00003,,
25.6018,-3.3154,-646.05037,4.1294,0.00003,,
25.6228,-3.31745,-645.72818,4.12734,0.00003,,
25.6478,-3.32001,-645.7136,4.12725,0.00003,,
25.6708,-3.32236,-644.4755,4.11934,0.00003,,
25.7,-3.32523,-642.8536,4.10897,0.00003,,
25.7248,-3.32767,-640.5002,4.09393,0.00003,,
25.7518,-3.33036,-637.53906,4.075,0.00003,,
25.7788,-3.33313,-636.37812,4.06758,0.00003,,
25.8028,-3.33556,-635.93783,4.06476,0.00003,,
25.8258,-3.33783,-633.40198,4.04856,0.00003,,
25.8538,-3.34057,-629.12097,4.02119,0.00003,,
25.8888,-3.34414,-626.3657,4.00358,0.00003,,
25.9118,-3.3465,-626.08868,4.00181,0.00003,,
25.9348,-3.3488,-626.04155,4.00151,0.00003,,
25.9658,-3.35182,-625.491,3.99799,0.00003,,
25.9918,-3.35443,-626.05306,4.00158,0.00003,,
26.0158,-3.35693,-626.27331,4.00299,0.00003,,
26.0408,-3.35946,-626.09422,4.00185,0.00003,,
26.0638,-3.36173,-626.20318,4.00254,0.00003,,
26.0898,-3.36425,-625.584,3.99859,0.00003,,
26.1248,-3.36779,-624.46678,3.99144,0.00003,,
26.1498,-3.37033,-625.12094,3.99563,0.00003,,
26.1818,-3.37349,-625.31936,3.99689,0.00003,,
26.2098,-3.3762,-624.98953,3.99479,0.00003,,
26.2358,-3.37879,-625.07889,3.99536,0.00003,,
26.2618,-3.38144,-624.88266,3.9941,0.00003,,
26.2828,-3.38353,-624.30659,3.99042,0.00003,,
26.3038,-3.38559,-623.56442,3.98568,0.00003,,
26.3348,-3.38862,-621.59747,3.9731,0.00003,,
26.3648,-3.39169,-620.58144,3.96661,0.00003,,
26.4018,-3.39544,-619.17077,3.95759,0.00003,,
26.4298,-3.3982,-618.90073,3.95587,0.00003,,
26.4538,-3.40057,-619.3189,3.95854,0.00003,,
26.4828,-3.40352,-618.75181,3.95492,0.00003,,
26.5068,-3.40597,-617.88503,3.94938,0.00003,,
26.5338,-3.40867,-618.29118,3.95197,0.00003,,
26.5578,-3.41104,-617.83101,3.94903,0.00003,,
26.5958,-3.41488,-616.79375,3.9424,0.00003,,
26.6138,-3.41673,-616.61052,3.94123,0.00003,,
26.6358,-3.41894,-616.71031,3.94187,0.00003,,
26.6618,-3.42152,-614.20016,3.92582,0.00003,,
26.6958,-3.42485,-612.43554,3.91454,0.00003,,
26.7198,-3.42729,-612.27027,3.91349,0.00003,,
26.7508,-3.43042,-612.6543,3.91594,0.00003,,
26.7828,-3.43358,-611.73644,3.91008,0.00003,,
26.8138,-3.43661,-610.8609,3.90448,0.00003,,
26.8398,-3.43924,-611.04721,3.90567,0.00003,,
26.8598,-3.44126,-610.37303,3.90136,0.00003,,
26.8838,-3.44366,-610.09754,3.8996,0.00003,,
26.9108,-3.44631,-609.70802,3.89711,0.00003,,
26.9468,-3.44987,-608.46549,3.88917,0.00003,,
26.9688,-3.45212,-608.79835,3.8913,0.00003,,
26.9938,-3.45463,-608.73018,3.89086,0.00003,,
27.0208,-3.45731,-607.92253,3.8857,0.00003,,
27.0648,-3.46171,-606.03037,3.8736,0.00003,,
27.0848,-3.46376,-606.40541,3.876,0.00003,,
27.1078,-3.46606,-607.3317,3.88192,0.00003,,
27.1388,-3.46914,-606.64099,3.87751,0.00003,,
27.1658,-3.47182,-605.88699,3.87269,0.00003,,
27.1948,-3.47478,-606.1933,3.87464,0.00003,,
27.2178,-3.47712,-606.42762,3.87614,0.00003,,
27.2538,-3.48068,-605.42733,3.86975,0.00003,,
27.2858,-3.48384,-604.98705,3.86694,0.00003,,
27.3058,-3.48588,-601.7922,3.84651,0.00003,,
27.3368,-3.48904,-596.70648,3.81401,0.00003,,
27.3638,-3.49169,-595.54046,3.80655,0.00003,,
27.3858,-3.49385,-592.32041,3.78597,0.00003,,
27.4128,-3.49653,-588.98097,3.76463,0.00003,,
27.4398,-3.49929,-586.90989,3.75139,0.00003,,
27.4648,-3.5018,-585.39938,3.74173,0.00003,,
27.4908,-3.50435,-585.29843,3.74109,0.00003,,
27.5178,-3.50698,-585.15347,3.74016,0.00003,,
27.5418,-3.50939,-585.28418,3.741,0.00003,,
27.5748,-3.51273,-585.25056,3.74078,0.00003,,
27.6068,-3.51591,-585.34811,3.74141,0.00003,,
27.6318,-3.51836,-586.02062,3.74571,0.00003,,
27.6678,-3.52201,-586.2725,3.74732,0.00003,,
27.6948,-3.52477,-586.53178,3.74897,0.00003,,
27.7148,-3.52673,-587.31991,3.75401,0.00003,,
27.7398,-3.52918,-587.91051,3.75779,0.00003,,
27.7698,-3.53221,-587.90594,3.75776,0.00003,,
27.7908,-3.53439,-588.65799,3.76256,0.00003,,
27.8158,-3.53692,-589.33366,3.76688,0.00003,,
27.8488,-3.54017,-589.22814,3.76621,0.00003,,
27.8778,-3.54303,-589.67946,3.76909,0.00003,,
27.9068,-3.54598,-589.77357,3.76969,0.00003,,
27.9308,-3.54843,-590.15942,3.77216,0.00003,,
27.9628,-3.5516,-590.20477,3.77245,0.00003,,
27.9858,-3.55383,-590.05199,3.77147,0.00003,,
28.0058,-3.55582,-589.15112,3.76572,0.00003,,
28.0338,-3.5587,-579.49321,3.70398,0.00003,,
28.0638,-3.56172,-575.33444,3.6774,0.00003,,
28.0918,-3.56442,-575.23698,3.67678,0.00003,,
28.1188,-3.56705,-575.33556,3.67741,0.00003,,
28.1398,-3.56919,-572.18452,3.65727,0.00003,,
28.1498,-3.57022,-567.21722,3.62552,0.00003,,